[2024-11-28T04:06:47.045+0000] {local_task_job_runner.py:123} INFO - ::group::Pre task execution logs
[2024-11-28T04:06:47.061+0000] {taskinstance.py:2613} INFO - Dependencies all met for dep_context=non-requeueable deps ti=<TaskInstance: brewery_bronze_layer.load_bronze manual__2024-11-28T04:04:46.835138+00:00 [queued]>
[2024-11-28T04:06:47.068+0000] {taskinstance.py:2613} INFO - Dependencies all met for dep_context=requeueable deps ti=<TaskInstance: brewery_bronze_layer.load_bronze manual__2024-11-28T04:04:46.835138+00:00 [queued]>
[2024-11-28T04:06:47.069+0000] {taskinstance.py:2866} INFO - Starting attempt 1 of 2
[2024-11-28T04:06:47.080+0000] {taskinstance.py:2889} INFO - Executing <Task(PythonOperator): load_bronze> on 2024-11-28 04:04:46.835138+00:00
[2024-11-28T04:06:47.085+0000] {standard_task_runner.py:72} INFO - Started process 188 to run task
[2024-11-28T04:06:47.089+0000] {standard_task_runner.py:104} INFO - Running: ['***', 'tasks', 'run', 'brewery_bronze_layer', 'load_bronze', 'manual__2024-11-28T04:04:46.835138+00:00', '--job-id', '127', '--raw', '--subdir', 'DAGS_FOLDER/openbrewery_dag.py', '--cfg-path', '/tmp/tmp0dbftgtz']
[2024-11-28T04:06:47.091+0000] {standard_task_runner.py:105} INFO - Job 127: Subtask load_bronze
[2024-11-28T04:06:47.154+0000] {task_command.py:467} INFO - Running <TaskInstance: brewery_bronze_layer.load_bronze manual__2024-11-28T04:04:46.835138+00:00 [running]> on host 0cf0280674ba
[2024-11-28T04:06:47.231+0000] {taskinstance.py:3132} INFO - Exporting env vars: AIRFLOW_CTX_DAG_OWNER='***' AIRFLOW_CTX_DAG_ID='brewery_bronze_layer' AIRFLOW_CTX_TASK_ID='load_bronze' AIRFLOW_CTX_EXECUTION_DATE='2024-11-28T04:04:46.835138+00:00' AIRFLOW_CTX_TRY_NUMBER='1' AIRFLOW_CTX_DAG_RUN_ID='manual__2024-11-28T04:04:46.835138+00:00'
[2024-11-28T04:06:47.232+0000] {taskinstance.py:731} INFO - ::endgroup::
[2024-11-28T04:06:47.247+0000] {load_bronze_module.py:109} INFO - Iniciando a tarefa load_bronze
[2024-11-28T04:06:47.413+0000] {load_bronze_module.py:128} INFO - Recebidos 8355 registros para carregar na camada Bronze
[2024-11-28T04:06:47.414+0000] {load_bronze_module.py:43} INFO - Iniciando criação da sessão Spark
[2024-11-28T04:07:08.743+0000] {load_bronze_module.py:67} INFO - Sessão Spark criada com sucesso
[2024-11-28T04:07:08.744+0000] {load_bronze_module.py:132} INFO - Sessão Spark criada com sucesso
[2024-11-28T04:07:08.745+0000] {load_bronze_module.py:152} INFO - Criando DataFrame com Spark
[2024-11-28T04:07:11.841+0000] {load_bronze_module.py:155} INFO - DataFrame criado com sucesso
[2024-11-28T04:07:11.842+0000] {load_bronze_module.py:157} INFO - Verificando dados que não atendem ao padrão
[2024-11-28T04:07:33.752+0000] {local_task_job_runner.py:127} ERROR - Received SIGTERM. Terminating subprocesses
[2024-11-28T04:07:33.760+0000] {process_utils.py:132} INFO - Sending 15 to group 188. PIDs of all processes in the group: [190, 348, 413, 428, 432, 435, 440, 445, 449, 454, 457, 461, 465, 468, 471, 362, 363, 368, 374, 377, 382, 387, 390, 392, 397, 399, 402, 188]
[2024-11-28T04:07:33.761+0000] {process_utils.py:87} INFO - Sending the signal 15 to group 188
[2024-11-28T04:07:33.762+0000] {taskinstance.py:3093} ERROR - Received SIGTERM. Terminating subprocesses.
[2024-11-28T04:07:34.137+0000] {process_utils.py:80} INFO - Process psutil.Process(pid=465, status='terminated', started='04:07:15') (465) terminated with exit code None
[2024-11-28T04:07:34.138+0000] {process_utils.py:80} INFO - Process psutil.Process(pid=445, status='terminated', started='04:07:14') (445) terminated with exit code None
[2024-11-28T04:07:34.165+0000] {process_utils.py:80} INFO - Process psutil.Process(pid=413, status='terminated', started='04:07:14') (413) terminated with exit code None
[2024-11-28T04:07:34.166+0000] {process_utils.py:80} INFO - Process psutil.Process(pid=435, status='terminated', started='04:07:14') (435) terminated with exit code None
[2024-11-28T04:07:34.166+0000] {process_utils.py:80} INFO - Process psutil.Process(pid=374, status='terminated', started='04:07:13') (374) terminated with exit code None
[2024-11-28T04:07:34.166+0000] {process_utils.py:80} INFO - Process psutil.Process(pid=387, status='terminated', started='04:07:13') (387) terminated with exit code None
[2024-11-28T04:07:34.167+0000] {process_utils.py:80} INFO - Process psutil.Process(pid=377, status='terminated', started='04:07:13') (377) terminated with exit code None
[2024-11-28T04:07:34.219+0000] {process_utils.py:80} INFO - Process psutil.Process(pid=348, status='terminated', started='04:07:12') (348) terminated with exit code None
[2024-11-28T04:07:34.220+0000] {process_utils.py:80} INFO - Process psutil.Process(pid=397, status='terminated', started='04:07:13') (397) terminated with exit code None
[2024-11-28T04:07:34.220+0000] {process_utils.py:80} INFO - Process psutil.Process(pid=461, status='terminated', started='04:07:14') (461) terminated with exit code None
[2024-11-28T04:07:34.221+0000] {process_utils.py:80} INFO - Process psutil.Process(pid=440, status='terminated', started='04:07:14') (440) terminated with exit code None
[2024-11-28T04:07:34.221+0000] {process_utils.py:80} INFO - Process psutil.Process(pid=432, status='terminated', started='04:07:14') (432) terminated with exit code None
[2024-11-28T04:07:34.221+0000] {process_utils.py:80} INFO - Process psutil.Process(pid=368, status='terminated', started='04:07:13') (368) terminated with exit code None
[2024-11-28T04:07:34.221+0000] {process_utils.py:80} INFO - Process psutil.Process(pid=402, status='terminated', started='04:07:13') (402) terminated with exit code None
[2024-11-28T04:07:34.222+0000] {process_utils.py:80} INFO - Process psutil.Process(pid=392, status='terminated', started='04:07:13') (392) terminated with exit code None
[2024-11-28T04:07:34.222+0000] {process_utils.py:80} INFO - Process psutil.Process(pid=382, status='terminated', started='04:07:13') (382) terminated with exit code None
[2024-11-28T04:07:34.222+0000] {process_utils.py:80} INFO - Process psutil.Process(pid=454, status='terminated', started='04:07:14') (454) terminated with exit code None
[2024-11-28T04:07:34.223+0000] {process_utils.py:80} INFO - Process psutil.Process(pid=457, status='terminated', started='04:07:14') (457) terminated with exit code None
[2024-11-28T04:07:34.223+0000] {process_utils.py:80} INFO - Process psutil.Process(pid=362, status='terminated', started='04:07:13') (362) terminated with exit code None
[2024-11-28T04:07:34.223+0000] {process_utils.py:80} INFO - Process psutil.Process(pid=363, status='terminated', started='04:07:13') (363) terminated with exit code None
[2024-11-28T04:07:34.223+0000] {process_utils.py:80} INFO - Process psutil.Process(pid=399, status='terminated', started='04:07:13') (399) terminated with exit code None
[2024-11-28T04:07:34.555+0000] {clientserver.py:538} INFO - Error while receiving.
Traceback (most recent call last):
  File "/opt/airflow/scripts/load_bronze_module.py", line 162, in load_bronze
    invalid_longitudes = df_spark.filter(~col("is_valid_longitude")).count()
  File "/home/airflow/.local/lib/python3.9/site-packages/pyspark/sql/dataframe.py", line 1193, in count
    return int(self._jdf.count())
  File "/home/airflow/.local/lib/python3.9/site-packages/py4j/java_gateway.py", line 1321, in __call__
    answer = self.gateway_client.send_command(command)
  File "/home/airflow/.local/lib/python3.9/site-packages/py4j/java_gateway.py", line 1038, in send_command
    response = connection.send_command(command)
  File "/home/airflow/.local/lib/python3.9/site-packages/py4j/clientserver.py", line 511, in send_command
    answer = smart_decode(self.stream.readline()[:-1])
  File "/usr/local/lib/python3.9/socket.py", line 716, in readinto
    return self._sock.recv_into(b)
  File "/home/airflow/.local/lib/python3.9/site-packages/airflow/models/taskinstance.py", line 3095, in signal_handler
    raise AirflowTaskTerminated("Task received SIGTERM signal")
airflow.exceptions.AirflowTaskTerminated: Task received SIGTERM signal

During handling of the above exception, another exception occurred:

Traceback (most recent call last):
  File "/home/airflow/.local/lib/python3.9/site-packages/py4j/clientserver.py", line 511, in send_command
    answer = smart_decode(self.stream.readline()[:-1])
  File "/usr/local/lib/python3.9/socket.py", line 716, in readinto
    return self._sock.recv_into(b)
ConnectionResetError: [Errno 104] Connection reset by peer
[2024-11-28T04:07:34.560+0000] {clientserver.py:543} INFO - Closing down clientserver connection
[2024-11-28T04:07:34.561+0000] {java_gateway.py:1055} ERROR - Exception while sending command.
Traceback (most recent call last):
  File "/opt/airflow/scripts/load_bronze_module.py", line 162, in load_bronze
    invalid_longitudes = df_spark.filter(~col("is_valid_longitude")).count()
  File "/home/airflow/.local/lib/python3.9/site-packages/pyspark/sql/dataframe.py", line 1193, in count
    return int(self._jdf.count())
  File "/home/airflow/.local/lib/python3.9/site-packages/py4j/java_gateway.py", line 1321, in __call__
    answer = self.gateway_client.send_command(command)
  File "/home/airflow/.local/lib/python3.9/site-packages/py4j/java_gateway.py", line 1038, in send_command
    response = connection.send_command(command)
  File "/home/airflow/.local/lib/python3.9/site-packages/py4j/clientserver.py", line 511, in send_command
    answer = smart_decode(self.stream.readline()[:-1])
  File "/usr/local/lib/python3.9/socket.py", line 716, in readinto
    return self._sock.recv_into(b)
  File "/home/airflow/.local/lib/python3.9/site-packages/airflow/models/taskinstance.py", line 3095, in signal_handler
    raise AirflowTaskTerminated("Task received SIGTERM signal")
airflow.exceptions.AirflowTaskTerminated: Task received SIGTERM signal

During handling of the above exception, another exception occurred:

Traceback (most recent call last):
  File "/home/airflow/.local/lib/python3.9/site-packages/py4j/clientserver.py", line 511, in send_command
    answer = smart_decode(self.stream.readline()[:-1])
  File "/usr/local/lib/python3.9/socket.py", line 716, in readinto
    return self._sock.recv_into(b)
ConnectionResetError: [Errno 104] Connection reset by peer

During handling of the above exception, another exception occurred:

Traceback (most recent call last):
  File "/home/airflow/.local/lib/python3.9/site-packages/py4j/java_gateway.py", line 1038, in send_command
    response = connection.send_command(command)
  File "/home/airflow/.local/lib/python3.9/site-packages/py4j/clientserver.py", line 539, in send_command
    raise Py4JNetworkError(
py4j.protocol.Py4JNetworkError: Error while sending or receiving
[2024-11-28T04:07:34.563+0000] {logging_mixin.py:190} WARNING - /home/***/.local/lib/python3.9/site-packages/pyspark/context.py:654 RuntimeWarning: Unable to cleanly shutdown Spark JVM process. It is possible that the process has crashed, been killed or may also be in a zombie state.
[2024-11-28T04:07:34.568+0000] {process_utils.py:80} INFO - Process psutil.Process(pid=449, status='terminated', started='04:07:14') (449) terminated with exit code None
[2024-11-28T04:07:34.569+0000] {process_utils.py:80} INFO - Process psutil.Process(pid=428, status='terminated', started='04:07:14') (428) terminated with exit code None
[2024-11-28T04:07:34.569+0000] {process_utils.py:80} INFO - Process psutil.Process(pid=390, status='terminated', started='04:07:13') (390) terminated with exit code None
[2024-11-28T04:07:34.570+0000] {process_utils.py:80} INFO - Process psutil.Process(pid=468, status='terminated', started='04:07:15') (468) terminated with exit code None
[2024-11-28T04:07:34.570+0000] {process_utils.py:80} INFO - Process psutil.Process(pid=471, status='terminated', started='04:07:15') (471) terminated with exit code None
[2024-11-28T04:07:34.884+0000] {clientserver.py:543} INFO - Closing down clientserver connection
[2024-11-28T04:07:34.885+0000] {taskinstance.py:3311} ERROR - Task failed with exception
Traceback (most recent call last):
  File "/opt/airflow/scripts/load_bronze_module.py", line 162, in load_bronze
    invalid_longitudes = df_spark.filter(~col("is_valid_longitude")).count()
  File "/home/airflow/.local/lib/python3.9/site-packages/pyspark/sql/dataframe.py", line 1193, in count
    return int(self._jdf.count())
  File "/home/airflow/.local/lib/python3.9/site-packages/py4j/java_gateway.py", line 1321, in __call__
    answer = self.gateway_client.send_command(command)
  File "/home/airflow/.local/lib/python3.9/site-packages/py4j/java_gateway.py", line 1038, in send_command
    response = connection.send_command(command)
  File "/home/airflow/.local/lib/python3.9/site-packages/py4j/clientserver.py", line 511, in send_command
    answer = smart_decode(self.stream.readline()[:-1])
  File "/usr/local/lib/python3.9/socket.py", line 716, in readinto
    return self._sock.recv_into(b)
  File "/home/airflow/.local/lib/python3.9/site-packages/airflow/models/taskinstance.py", line 3095, in signal_handler
    raise AirflowTaskTerminated("Task received SIGTERM signal")
airflow.exceptions.AirflowTaskTerminated: Task received SIGTERM signal

During handling of the above exception, another exception occurred:

Traceback (most recent call last):
  File "/home/airflow/.local/lib/python3.9/site-packages/airflow/models/taskinstance.py", line 767, in _execute_task
    result = _execute_callable(context=context, **execute_callable_kwargs)
  File "/home/airflow/.local/lib/python3.9/site-packages/airflow/models/taskinstance.py", line 733, in _execute_callable
    return ExecutionCallableRunner(
  File "/home/airflow/.local/lib/python3.9/site-packages/airflow/utils/operator_helpers.py", line 252, in run
    return self.func(*args, **kwargs)
  File "/home/airflow/.local/lib/python3.9/site-packages/airflow/models/baseoperator.py", line 417, in wrapper
    return func(self, *args, **kwargs)
  File "/home/airflow/.local/lib/python3.9/site-packages/airflow/operators/python.py", line 238, in execute
    return_value = self.execute_callable()
  File "/home/airflow/.local/lib/python3.9/site-packages/airflow/operators/python.py", line 256, in execute_callable
    return runner.run(*self.op_args, **self.op_kwargs)
  File "/home/airflow/.local/lib/python3.9/site-packages/airflow/utils/operator_helpers.py", line 252, in run
    return self.func(*args, **kwargs)
  File "/opt/airflow/scripts/load_bronze_module.py", line 189, in load_bronze
    spark.stop()
  File "/home/airflow/.local/lib/python3.9/site-packages/pyspark/sql/session.py", line 1602, in stop
    self._jvm.SparkSession.clearDefaultSession()
  File "/home/airflow/.local/lib/python3.9/site-packages/py4j/java_gateway.py", line 1712, in __getattr__
    answer = self._gateway_client.send_command(
  File "/home/airflow/.local/lib/python3.9/site-packages/py4j/java_gateway.py", line 1036, in send_command
    connection = self._get_connection()
  File "/home/airflow/.local/lib/python3.9/site-packages/py4j/clientserver.py", line 284, in _get_connection
    connection = self._create_new_connection()
  File "/home/airflow/.local/lib/python3.9/site-packages/py4j/clientserver.py", line 291, in _create_new_connection
    connection.connect_to_java_server()
  File "/home/airflow/.local/lib/python3.9/site-packages/py4j/clientserver.py", line 438, in connect_to_java_server
    self.socket.connect((self.java_address, self.java_port))
ConnectionRefusedError: [Errno 111] Connection refused
[2024-11-28T04:07:34.899+0000] {taskinstance.py:1225} INFO - Marking task as UP_FOR_RETRY. dag_id=brewery_bronze_layer, task_id=load_bronze, run_id=manual__2024-11-28T04:04:46.835138+00:00, execution_date=20241128T040446, start_date=20241128T040647, end_date=20241128T040734
[2024-11-28T04:07:34.922+0000] {taskinstance.py:340} INFO - ::group::Post task execution logs
[2024-11-28T04:07:34.924+0000] {standard_task_runner.py:124} ERROR - Failed to execute job 127 for task load_bronze ([Errno 111] Connection refused; 188)
Traceback (most recent call last):
  File "/opt/airflow/scripts/load_bronze_module.py", line 162, in load_bronze
    invalid_longitudes = df_spark.filter(~col("is_valid_longitude")).count()
  File "/home/airflow/.local/lib/python3.9/site-packages/pyspark/sql/dataframe.py", line 1193, in count
    return int(self._jdf.count())
  File "/home/airflow/.local/lib/python3.9/site-packages/py4j/java_gateway.py", line 1321, in __call__
    answer = self.gateway_client.send_command(command)
  File "/home/airflow/.local/lib/python3.9/site-packages/py4j/java_gateway.py", line 1038, in send_command
    response = connection.send_command(command)
  File "/home/airflow/.local/lib/python3.9/site-packages/py4j/clientserver.py", line 511, in send_command
    answer = smart_decode(self.stream.readline()[:-1])
  File "/usr/local/lib/python3.9/socket.py", line 716, in readinto
    return self._sock.recv_into(b)
  File "/home/airflow/.local/lib/python3.9/site-packages/airflow/models/taskinstance.py", line 3095, in signal_handler
    raise AirflowTaskTerminated("Task received SIGTERM signal")
airflow.exceptions.AirflowTaskTerminated: Task received SIGTERM signal

During handling of the above exception, another exception occurred:

Traceback (most recent call last):
  File "/home/airflow/.local/lib/python3.9/site-packages/airflow/task/task_runner/standard_task_runner.py", line 117, in _start_by_fork
    ret = args.func(args, dag=self.dag)
  File "/home/airflow/.local/lib/python3.9/site-packages/airflow/cli/cli_config.py", line 49, in command
    return func(*args, **kwargs)
  File "/home/airflow/.local/lib/python3.9/site-packages/airflow/utils/cli.py", line 116, in wrapper
    return f(*args, **kwargs)
  File "/home/airflow/.local/lib/python3.9/site-packages/airflow/cli/commands/task_command.py", line 483, in task_run
    task_return_code = _run_task_by_selected_method(args, _dag, ti)
  File "/home/airflow/.local/lib/python3.9/site-packages/airflow/cli/commands/task_command.py", line 256, in _run_task_by_selected_method
    return _run_raw_task(args, ti)
  File "/home/airflow/.local/lib/python3.9/site-packages/airflow/cli/commands/task_command.py", line 341, in _run_raw_task
    return ti._run_raw_task(
  File "/home/airflow/.local/lib/python3.9/site-packages/airflow/utils/session.py", line 97, in wrapper
    return func(*args, session=session, **kwargs)
  File "/home/airflow/.local/lib/python3.9/site-packages/airflow/models/taskinstance.py", line 3005, in _run_raw_task
    return _run_raw_task(
  File "/home/airflow/.local/lib/python3.9/site-packages/airflow/models/taskinstance.py", line 273, in _run_raw_task
    TaskInstance._execute_task_with_callbacks(
  File "/home/airflow/.local/lib/python3.9/site-packages/airflow/models/taskinstance.py", line 3159, in _execute_task_with_callbacks
    result = self._execute_task(context, task_orig)
  File "/home/airflow/.local/lib/python3.9/site-packages/airflow/models/taskinstance.py", line 3183, in _execute_task
    return _execute_task(self, context, task_orig)
  File "/home/airflow/.local/lib/python3.9/site-packages/airflow/models/taskinstance.py", line 767, in _execute_task
    result = _execute_callable(context=context, **execute_callable_kwargs)
  File "/home/airflow/.local/lib/python3.9/site-packages/airflow/models/taskinstance.py", line 733, in _execute_callable
    return ExecutionCallableRunner(
  File "/home/airflow/.local/lib/python3.9/site-packages/airflow/utils/operator_helpers.py", line 252, in run
    return self.func(*args, **kwargs)
  File "/home/airflow/.local/lib/python3.9/site-packages/airflow/models/baseoperator.py", line 417, in wrapper
    return func(self, *args, **kwargs)
  File "/home/airflow/.local/lib/python3.9/site-packages/airflow/operators/python.py", line 238, in execute
    return_value = self.execute_callable()
  File "/home/airflow/.local/lib/python3.9/site-packages/airflow/operators/python.py", line 256, in execute_callable
    return runner.run(*self.op_args, **self.op_kwargs)
  File "/home/airflow/.local/lib/python3.9/site-packages/airflow/utils/operator_helpers.py", line 252, in run
    return self.func(*args, **kwargs)
  File "/opt/airflow/scripts/load_bronze_module.py", line 189, in load_bronze
    spark.stop()
  File "/home/airflow/.local/lib/python3.9/site-packages/pyspark/sql/session.py", line 1602, in stop
    self._jvm.SparkSession.clearDefaultSession()
  File "/home/airflow/.local/lib/python3.9/site-packages/py4j/java_gateway.py", line 1712, in __getattr__
    answer = self._gateway_client.send_command(
  File "/home/airflow/.local/lib/python3.9/site-packages/py4j/java_gateway.py", line 1036, in send_command
    connection = self._get_connection()
  File "/home/airflow/.local/lib/python3.9/site-packages/py4j/clientserver.py", line 284, in _get_connection
    connection = self._create_new_connection()
  File "/home/airflow/.local/lib/python3.9/site-packages/py4j/clientserver.py", line 291, in _create_new_connection
    connection.connect_to_java_server()
  File "/home/airflow/.local/lib/python3.9/site-packages/py4j/clientserver.py", line 438, in connect_to_java_server
    self.socket.connect((self.java_address, self.java_port))
ConnectionRefusedError: [Errno 111] Connection refused
[2024-11-28T04:07:34.953+0000] {process_utils.py:80} INFO - Process psutil.Process(pid=190, status='terminated', started='04:06:47') (190) terminated with exit code None
[2024-11-28T04:07:34.954+0000] {process_utils.py:80} INFO - Process psutil.Process(pid=188, status='terminated', exitcode=1, started='04:06:46') (188) terminated with exit code 1
[2024-11-28T04:07:34.955+0000] {local_task_job_runner.py:266} INFO - Task exited with return code 143
[2024-11-28T04:07:34.974+0000] {taskinstance.py:3895} INFO - 0 downstream tasks scheduled from follow-on schedule check
[2024-11-28T04:07:34.982+0000] {local_task_job_runner.py:245} INFO - ::endgroup::
[2024-11-28T04:07:41.912+0000] {local_task_job_runner.py:123} INFO - ::group::Pre task execution logs
[2024-11-28T04:07:41.925+0000] {taskinstance.py:2603} INFO - Dependencies not met for <TaskInstance: brewery_bronze_layer.load_bronze manual__2024-11-28T04:04:46.835138+00:00 [up_for_retry]>, dependency 'Not In Retry Period' FAILED: Task is not ready for retry yet but will be retried automatically. Current date is 2024-11-28T04:07:41.925312+00:00 and task will be retried at 2024-11-28T04:12:34.898590+00:00.
[2024-11-28T04:07:41.926+0000] {local_task_job_runner.py:166} INFO - Task is not able to be run
